<?xml version="1.0" encoding="utf-8"?>
<robot  name="ddrobot" xmlns:xacro="http://ros.org/wiki/xacro">
<xacro:include filename="$(find ddrobot_description)/urdf/common_properties.xacro"/>

<!--Base_footprint-->
<link name="base_footprint"> </link>
<joint
    name="base_footprint_to_base"
    type="fixed">
    <origin xyz="0 0 0.0275" rpy="0 0 0" />
    <parent link= "base_footprint"/>
    <child link="base_link"/>
</joint>

<!--Base_link-->
<link name="base_link">
   
    <xacro:cylinder_inertia m="0.254469" r="0.15" h="0.005"/>
    
    <visual>
        <origin xyz="0.0 0.0 0.0" rpy="0.0 0.0 0.0"/>
        <geometry>
            <cylinder length="0.003" radius="0.15"/>
        </geometry>
        <material name="blue">
            <color rgba="1.0 0.0 0.0 1.0"/>
            <texture filename=""/>
        </material>
    </visual>
    <collision>
        <origin xyz="0.0 0.0 0.0" rpy="0.0 0.0 0.0"/>
        <geometry>
            <cylinder length="0.003" radius="0.15"/>
        </geometry>
    </collision>
</link>

<!-- Right Wheel -->
  <link name="right_wheel">
    <visual>
      <origin xyz="0 0 0" rpy="1.570795 0 0" />
      <geometry>
          <cylinder length="0.03" radius="0.05" />
      </geometry>
      <material name="black" />
    </visual>
    <!-- Right Wheel collision, mass and inertia -->
    <collision>
      <origin xyz="0 0 0" rpy="1.570795 0 0" />
      <geometry>
          <cylinder length="0.03" radius="0.05" />
      </geometry>
    </collision>

    <xacro:cylinder_inertia m="0.18" r="0.05" h="0.03"/>
  </link>

<joint name="base_to_right_wheel" type="continuous">
    <origin xyz="0 -0.1175 0.025" rpy="0 0 0" />
    <parent link="base_link" />
    <child link="right_wheel" />
    <axis xyz="0 1 0" />
</joint>

<!-- Left Wheel -->
  <link name="left_wheel">
    <visual>
      <origin xyz="0 0 0" rpy="1.570795 0 0" />
      <geometry>
          <cylinder length="0.03" radius="0.05" />
      </geometry>
      <material name="black" />
    </visual>

    <!-- Left Wheel collision, mass and inertia -->
    <collision>
      <origin xyz="0 0 0" rpy="1.570795 0 0" />
      <geometry>
          <cylinder length="0.03" radius="0.05" />
      </geometry>
    </collision>

    <xacro:cylinder_inertia m="0.18" r="0.05" h="0.03"/>

  </link>

<joint
    name="base_to_left_wheel"
    type="continuous">
    <origin xyz="0 0.1175 0.025" rpy="0 0 0" />
    <parent link="base_link" />
    <child link="left_wheel" />
    <axis xyz="0 1 0" />
</joint>

<!--Caster_front_link-->
  <link name="caster_front_wheel">
    <visual>
      <origin xyz="0 0 0" rpy="0 0 0" />
      <geometry>
          <sphere radius="0.0125" />
      </geometry>
      <material name="white" />
    </visual>

    <!--collision, mass and inertia -->
    <collision>
      <origin xyz="0 0 0" rpy="0 0 0" />
      <geometry>
          <sphere radius="0.0125" />
      </geometry>
    </collision>

    <xacro:sphere_inertia m="0.05" r="0.0125"/>

  </link>

  <joint
    name="base_to_caster_front"
    type="fixed">
    <origin xyz="0.1 0.0 -0.0125" rpy="0.0 0.0 0.0" />
    <parent link="base_link" />
    <child link="caster_front_wheel" />
  </joint>

<!--Caster_back_link-->
  <link name="caster_back_wheel">
    <visual>
      <origin xyz="0 0 0" rpy="0 0 0" />
      <geometry>
          <sphere radius="0.0125" />
      </geometry>
      <material name="white" />
    </visual>

    <!--collision, mass and inertia -->
    <collision>
      <origin xyz="0 0 0" rpy="0 0 0" />
      <geometry>
        <sphere radius="0.0125" />
      </geometry>
    </collision>

    <xacro:sphere_inertia m="0.05" r="0.0125"/>

  </link>

  <joint
    name="base_to_caster_back"
    type="fixed">
    <origin xyz="-0.1 0.0 -0.0125" rpy="0.0 0.0 0.0" />
    <parent link="base_link" />
    <child link="caster_back_wheel" />
  </joint>

<!--pillar_11-->
  <link name="pillar_11">
    <visual>
      <origin xyz="0 0 0" rpy="0 0 0" />
      <geometry>
          <box size="0.01 0.01 0.06" />
      </geometry>
      <material name="white" />
    </visual>

    <!--collision, mass and inertia -->
    <collision>
      <origin xyz="0 0 0" rpy="0 0 0" />
      <geometry>
          <box size="0.01 0.01 0.06" />
      </geometry>
    </collision>

    <xacro:box_inertia m="0.08" w="0.01" h="0.06" d="0.01"/>

  </link>

  <joint
    name="base_to_pillar_11"
    type="fixed">
    <origin xyz="0.1 0.07 0.03" rpy="0.0 0.0 0.0" />
    <parent link="base_link" />
    <child link="pillar_11" />
  </joint>

  <!--pillar_12-->
  <link name="pillar_12">
    <visual>
      <origin xyz="0 0 0" rpy="0 0 0" />
      <geometry>
          <box size="0.01 0.01 0.06" />
      </geometry>
      <material name="white" />
    </visual>

    <!--collision, mass and inertia -->
    <collision>
      <origin xyz="0 0 0" rpy="0 0 0" />
      <geometry>
          <box size="0.01 0.01 0.06" />
      </geometry>
    </collision>

    <xacro:box_inertia m="0.08" w="0.01" h="0.06" d="0.01"/>

  </link>

  <joint
    name="base_to_pillar_12"
    type="fixed">
    <origin xyz="0.1 -0.07 0.03" rpy="0.0 0.0 0.0" />
    <parent link="base_link" />
    <child link="pillar_12" />
  </joint>

  <!--pillar_13-->
  <link name="pillar_13">
    <visual>
      <origin xyz="0 0 0" rpy="0 0 0" />
      <geometry>
          <box size="0.01 0.01 0.06" />
      </geometry>
      <material name="white" />
    </visual>

    <!--collision, mass and inertia -->
    <collision>
      <origin xyz="0 0 0" rpy="0 0 0" />
      <geometry>
          <box size="0.01 0.01 0.06" />
      </geometry>
    </collision>

    <xacro:box_inertia m="0.08" w="0.01" h="0.06" d="0.01"/>

  </link>

  <joint
    name="base_to_pillar_13"
    type="fixed">
    <origin xyz="-0.1 -0.07 0.03" rpy="0.0 0.0 0.0" />
    <parent link="base_link" />
    <child link="pillar_13" />
  </joint>

  <!--pillar_14-->
  <link name="pillar_14">
    <visual>
      <origin xyz="0 0 0" rpy="0 0 0" />
      <geometry>
          <box size="0.01 0.01 0.06" />
      </geometry>
      <material name="white" />
    </visual>

    <!--collision, mass and inertia -->
    <collision>
      <origin xyz="0 0 0" rpy="0 0 0" />
      <geometry>
          <box size="0.01 0.01 0.06" />
      </geometry>
    </collision>

    <xacro:box_inertia m="0.08" w="0.01" h="0.06" d="0.01"/>

  </link>

  <joint
    name="base_to_pillar_14"
    type="fixed">
    <origin xyz="-0.1 0.07 0.03" rpy="0.0 0.0 0.0" />
    <parent link="base_link" />
    <child link="pillar_14" />
  </joint>

  <!--floor_link_2-->
<link name="floor_link_2">
   
    <xacro:cylinder_inertia m="0.254469" r="0.15" h="0.003"/>
    
    <visual>
        <origin xyz="0.0 0.0 0.0" rpy="0.0 0.0 0.0"/>
        <geometry>
            <cylinder length="0.003" radius="0.15"/>
        </geometry>
        <material name="blue">
            <color rgba="1.0 0.0 0.0 1.0"/>
            <texture filename=""/>
        </material>
    </visual>
    <collision>
        <origin xyz="0.0 0.0 0.0" rpy="0.0 0.0 0.0"/>
        <geometry>
            <cylinder length="0.003" radius="0.15"/>
        </geometry>
    </collision>
</link>

<joint
    name="base_to_floor2"
    type="fixed">
    <origin xyz="0 0 0.0635" rpy="0 0 0" />
    <parent link= "base_link"/>
    <child link="floor_link_2"/>
</joint>

<!--pillar_11-->
  <link name="pillar_21">
    <visual>
      <origin xyz="0 0 0" rpy="0 0 0" />
      <geometry>
          <box size="0.01 0.01 0.06" />
      </geometry>
      <material name="white" />
    </visual>

    <!--collision, mass and inertia -->
    <collision>
      <origin xyz="0 0 0" rpy="0 0 0" />
      <geometry>
          <box size="0.01 0.01 0.06" />
      </geometry>
    </collision>

    <xacro:box_inertia m="0.08" w="0.01" h="0.06" d="0.01"/>

  </link>

  <joint
    name="floor2_to_pillar_21"
    type="fixed">
    <origin xyz="0.1 0.07 0.03" rpy="0.0 0.0 0.0" />
    <parent link="floor_link_2" />
    <child link="pillar_21" />
  </joint>

  <!--pillar_12-->
  <link name="pillar_22">
    <visual>
      <origin xyz="0 0 0" rpy="0 0 0" />
      <geometry>
          <box size="0.01 0.01 0.06" />
      </geometry>
      <material name="white" />
    </visual>

    <!--collision, mass and inertia -->
    <collision>
      <origin xyz="0 0 0" rpy="0 0 0" />
      <geometry>
          <box size="0.01 0.01 0.06" />
      </geometry>
    </collision>

    <xacro:box_inertia m="0.08" w="0.01" h="0.06" d="0.01"/>

  </link>

  <joint
    name="floor2_to_pillar_22"
    type="fixed">
    <origin xyz="0.1 -0.07 0.03" rpy="0.0 0.0 0.0" />
    <parent link="floor_link_2" />
    <child link="pillar_22" />
  </joint>

  <!--pillar_13-->
  <link name="pillar_23">
    <visual>
      <origin xyz="0 0 0" rpy="0 0 0" />
      <geometry>
          <box size="0.01 0.01 0.06" />
      </geometry>
      <material name="white" />
    </visual>

    <!--collision, mass and inertia -->
    <collision>
      <origin xyz="0 0 0" rpy="0 0 0" />
      <geometry>
          <box size="0.01 0.01 0.06" />
      </geometry>
    </collision>

    <xacro:box_inertia m="0.08" w="0.01" h="0.06" d="0.01"/>

  </link>

  <joint
    name="base_to_pillar_23"
    type="fixed">
    <origin xyz="-0.1 -0.07 0.03" rpy="0.0 0.0 0.0" />
    <parent link="floor_link_2" />
    <child link="pillar_23" />
  </joint>

  <!--pillar_14-->
  <link name="pillar_24">
    <visual>
      <origin xyz="0 0 0" rpy="0 0 0" />
      <geometry>
          <box size="0.01 0.01 0.06" />
      </geometry>
      <material name="white" />
    </visual>

    <!--collision, mass and inertia -->
    <collision>
      <origin xyz="0 0 0" rpy="0 0 0" />
      <geometry>
          <box size="0.01 0.01 0.06" />
      </geometry>
    </collision>

    <xacro:box_inertia m="0.08" w="0.01" h="0.06" d="0.01"/>

  </link>

  <joint
    name="base_to_pillar_24"
    type="fixed">
    <origin xyz="-0.1 0.07 0.03" rpy="0.0 0.0 0.0" />
    <parent link="floor_link_2" />
    <child link="pillar_24" />
  </joint>

  <!--IMU_link-->
  <link name="imu_link"/>
  
  <joint name="imu_joint" type="fixed">
    <child link="imu_link"/>
    <parent link="base_link"/>
    <origin xyz="0 0 0.07" rpy="0 0 0"/>
  </joint>


    <!--floor_link_3-->
<link name="floor_link_3">
   
    <xacro:cylinder_inertia m="0.254469" r="0.15" h="0.003"/>
    
    <visual>
        <origin xyz="0.0 0.0 0.0" rpy="0.0 0.0 0.0"/>
        <geometry>
            <cylinder length="0.003" radius="0.15"/>
        </geometry>
        <material name="blue">
            <color rgba="1.0 0.0 0.0 1.0"/>
            <texture filename=""/>
        </material>
    </visual>
    <collision>
        <origin xyz="0.0 0.0 0.0" rpy="0.0 0.0 0.0"/>
        <geometry>
            <cylinder length="0.003" radius="0.15"/>
        </geometry>
    </collision>
</link>

<joint
    name="base_to_floor3"
    type="fixed">
    <origin xyz="0 0 0.125" rpy="0 0 0" />
    <parent link= "base_link"/>
    <child link="floor_link_3"/>
</joint>

<!--pillar_11-->
  <link name="pillar_31">
    <visual>
      <origin xyz="0 0 0" rpy="0 0 0" />
      <geometry>
          <box size="0.01 0.01 0.06" />
      </geometry>
      <material name="white" />
    </visual>

    <!--collision, mass and inertia -->
    <collision>
      <origin xyz="0 0 0" rpy="0 0 0" />
      <geometry>
          <box size="0.01 0.01 0.06" />
      </geometry>
    </collision>

    <xacro:box_inertia m="0.08" w="0.01" h="0.06" d="0.01"/>

  </link>

  <joint
    name="floor3_to_pillar_31"
    type="fixed">
    <origin xyz="0.1 0.07 0.03" rpy="0.0 0.0 0.0" />
    <parent link="floor_link_3" />
    <child link="pillar_31" />
  </joint>

  <!--pillar_12-->
  <link name="pillar_32">
    <visual>
      <origin xyz="0 0 0" rpy="0 0 0" />
      <geometry>
          <box size="0.01 0.01 0.06" />
      </geometry>
      <material name="white" />
    </visual>

    <!--collision, mass and inertia -->
    <collision>
      <origin xyz="0 0 0" rpy="0 0 0" />
      <geometry>
          <box size="0.01 0.01 0.06" />
      </geometry>
    </collision>

    <xacro:box_inertia m="0.08" w="0.01" h="0.06" d="0.01"/>

  </link>

  <joint
    name="floor3_to_pillar_32"
    type="fixed">
    <origin xyz="0.1 -0.07 0.03" rpy="0.0 0.0 0.0" />
    <parent link="floor_link_3" />
    <child link="pillar_32" />
  </joint>

  <!--pillar_13-->
  <link name="pillar_33">
    <visual>
      <origin xyz="0 0 0" rpy="0 0 0" />
      <geometry>
          <box size="0.01 0.01 0.06" />
      </geometry>
      <material name="white" />
    </visual>

    <!--collision, mass and inertia -->
    <collision>
      <origin xyz="0 0 0" rpy="0 0 0" />
      <geometry>
          <box size="0.01 0.01 0.06" />
      </geometry>
    </collision>

    <xacro:box_inertia m="0.08" w="0.01" h="0.06" d="0.01"/>

  </link>

  <joint
    name="base_to_pillar_33"
    type="fixed">
    <origin xyz="-0.1 -0.07 0.03" rpy="0.0 0.0 0.0" />
    <parent link="floor_link_3" />
    <child link="pillar_33" />
  </joint>

  <!--pillar_14-->
  <link name="pillar_34">
    <visual>
      <origin xyz="0 0 0" rpy="0 0 0" />
      <geometry>
          <box size="0.01 0.01 0.06" />
      </geometry>
      <material name="white" />
    </visual>

    <!--collision, mass and inertia -->
    <collision>
      <origin xyz="0 0 0" rpy="0 0 0" />
      <geometry>
          <box size="0.01 0.01 0.06" />
      </geometry>
    </collision>

    <xacro:box_inertia m="0.08" w="0.01" h="0.06" d="0.01"/>

  </link>

  <joint
    name="base_to_pillar_34"
    type="fixed">
    <origin xyz="-0.1 0.07 0.03" rpy="0.0 0.0 0.0" />
    <parent link="floor_link_3" />
    <child link="pillar_34" />
  </joint>

    <!--floor_link_4-->
<link name="floor_link_4">
   
    <xacro:cylinder_inertia m="0.254469" r="0.15" h="0.003"/>
    
    <visual>
        <origin xyz="0.0 0.0 0.0" rpy="0.0 0.0 0.0"/>
        <geometry>
            <cylinder length="0.003" radius="0.15"/>
        </geometry>
        <material name="blue">
            <color rgba="1.0 0.0 0.0 1.0"/>
            <texture filename=""/>
        </material>
    </visual>
    <collision>
        <origin xyz="0.0 0.0 0.0" rpy="0.0 0.0 0.0"/>
        <geometry>
            <cylinder length="0.003" radius="0.15"/>
        </geometry>
    </collision>
</link>

<joint
    name="base_to_floor4"
    type="fixed">
    <origin xyz="0 0 0.185" rpy="0 0 0" />
    <parent link= "base_link"/>
    <child link="floor_link_4"/>
</joint>

<!--RPLIDAR-->
<link name="laser">
  <xacro:cylinder_inertia m="0.19" r="0.03" h="0.04"/>

  <visual>
    <origin xyz=" 0 0 0 " rpy="0 0 0" />
    <geometry>
      <cylinder length="0.04" radius="0.03"/>
    </geometry>
    <material name="black"/>
  </visual>

  <collision>
    <origin xyz="0.0 0.0 0.0" rpy="0 0 0" />
    <geometry>
      <cylinder length="0.04" radius="0.03"/>
    </geometry>
  </collision>
</link>

<joint
    name="base_to_laser"
    type="fixed">
    <origin xyz="0 0 0.205" rpy="0 0 0" />
    <parent link= "base_link"/>
    <child link="laser"/>
</joint>

</robot>